Workbook

Sheet Summary
A1: STAFF ATTENDANCE SUMMARY 2025
A2: Prepared: 25 February 2026 | Staff Only | Organized by Department: IT Department
A3: Legend: | B3: ON | C3: Present | D3: OFF | E3: Absent | F3: ½ | G3: Saturday | H3: — | I3: Sunday | J3: OT | K3: Overtime
U4: WEEKEND ROTATION & ATTENDANCE SUMMARY
A5: No | B5: Name | C5: Department | D5: Jan | E5: Feb | F5: Mar | G5: Apr | H5: May | I5: Jun | J5: Jul | K5: Aug | L5: Sep | M5: Oct | N5: Nov | O5: Dec | P5: Present | Q5: Absent | R5: Sundays | S5: Rate | U5: Yr Days Worked | V5: Yr Days OFF | W5: Yr Wknd Fri | X5: Yr Deduct Days | Y5: Sat OT Days | Z5: Sun OT Days | AA5: Total OT Days | AB5: Holidays Worked | AC5: Grand Total OT | AD5: OT Taken | AE5: OT Balance
A6: ► ADMN
A7: 97 | B7: Ndamukunda Flavien | C7: ADMN | D7: 0 | E7: 22 | F7: 18 | G7: 26 | H7: 15 | I7: 11 | J7: 20 | K7: 13 | L7: 27 | M7: 27 | N7: 24 | O7: 10 | P7: =IFERROR(INDEX(January!$AI:$AI,MATCH($A7,January!$A:$A,0)),0)+IFERROR(INDEX(February!$AF:$AF,MATCH($A7,February!$A:$A,0)),0)+IFERROR(INDEX(March!$AI:$AI,MATCH($A7,March!$A:$A,0)),0)+IFERROR(INDEX(April!$AH:$AH,MATCH($A7,April!$A:$A,0)),0)+IFERROR(INDEX(May!$AI:$AI,MATCH($A7,May!$A:$A,0)),0)+IFERROR(INDEX(June!$AH:$AH,MATCH($A7,June!$A:$A,0)),0)+IFERROR(INDEX(July!$AI:$AI,MATCH($A7,July!$A:$A,0)),0)+IFERROR(INDEX(August!$AI:$AI,MATCH($A7,August!$A:$A,0)),0)+IFERROR(INDEX(September!$AH:$AH,MATCH($A7,September!$A:$A,0)),0)+IFERROR(INDEX(October!$AI:$AI,MATCH($A7,October!$A:$A,0)),0)+IFERROR(INDEX(November!$AH:$AH,MATCH($A7,November!$A:$A,0)),0)+IFERROR(INDEX(December!$AI:$AI,MATCH($A7,December!$A:$A,0)),0) -> 178 | Q7: =IFERROR(INDEX(January!$AJ:$AJ,MATCH($A7,January!$A:$A,0)),0)+IFERROR(INDEX(February!$AG:$AG,MATCH($A7,February!$A:$A,0)),0)+IFERROR(INDEX(March!$AJ:$AJ,MATCH($A7,March!$A:$A,0)),0)+IFERROR(INDEX(April!$AI:$AI,MATCH($A7,April!$A:$A,0)),0)+IFERROR(INDEX(May!$AJ:$AJ,MATCH($A7,May!$A:$A,0)),0)+IFERROR(INDEX(June!$AI:$AI,MATCH($A7,June!$A:$A,0)),0)+IFERROR(INDEX(July!$AJ:$AJ,MATCH($A7,July!$A:$A,0)),0)+IFERROR(INDEX(August!$AJ:$AJ,MATCH($A7,August!$A:$A,0)),0)+IFERROR(INDEX(September!$AI:$AI,MATCH($A7,September!$A:$A,0)),0)+IFERROR(INDEX(October!$AJ:$AJ,MATCH($A7,October!$A:$A,0)),0)+IFERROR(INDEX(November!$AI:$AI,MATCH($A7,November!$A:$A,0)),0)+IFERROR(INDEX(December!$AJ:$AJ,MATCH($A7,December!$A:$A,0)),0) -> 83 | R7: =IFERROR(INDEX(January!$AK:$AK,MATCH($A7,January!$A:$A,0)),0)+IFERROR(INDEX(February!$AH:$AH,MATCH($A7,February!$A:$A,0)),0)+IFERROR(INDEX(March!$AK:$AK,MATCH($A7,March!$A:$A,0)),0)+IFERROR(INDEX(April!$AJ:$AJ,MATCH($A7,April!$A:$A,0)),0)+IFERROR(INDEX(May!$AK:$AK,MATCH($A7,May!$A:$A,0)),0)+IFERROR(INDEX(June!$AJ:$AJ,MATCH($A7,June!$A:$A,0)),0)+IFERROR(INDEX(July!$AK:$AK,MATCH($A7,July!$A:$A,0)),0)+IFERROR(INDEX(August!$AK:$AK,MATCH($A7,August!$A:$A,0)),0)+IFERROR(INDEX(September!$AJ:$AJ,MATCH($A7,September!$A:$A,0)),0)+IFERROR(INDEX(October!$AK:$AK,MATCH($A7,October!$A:$A,0)),0)+IFERROR(INDEX(November!$AJ:$AJ,MATCH($A7,November!$A:$A,0)),0)+IFERROR(INDEX(December!$AK:$AK,MATCH($A7,December!$A:$A,0)),0) -> 16 | S7: =IF((P7+Q7)=0,"",P7/(P7+Q7)) -> 0.68199234 | U7: =IFERROR(INDEX(January!$AQ:$AQ,MATCH($A7,January!$A:$A,0)),0)+IFERROR(INDEX(February!$AN:$AN,MATCH($A7,February!$A:$A,0)),0)+IFERROR(INDEX(March!$AQ:$AQ,MATCH($A7,March!$A:$A,0)),0)+IFERROR(INDEX(April!$AP:$AP,MATCH($A7,April!$A:$A,0)),0)+IFERROR(INDEX(May!$AQ:$AQ,MATCH($A7,May!$A:$A,0)),0)+IFERROR(INDEX(June!$AP:$AP,MATCH($A7,June!$A:$A,0)),0)+IFERROR(INDEX(July!$AQ:$AQ,MATCH($A7,July!$A:$A,0)),0)+IFERROR(INDEX(August!$AQ:$AQ,MATCH($A7,August!$A:$A,0)),0)+IFERROR(INDEX(September!$AP:$AP,MATCH($A7,September!$A:$A,0)),0)+IFERROR(INDEX(October!$AQ:$AQ,MATCH($A7,October!$A:$A,0)),0)+IFERROR(INDEX(November!$AP:$AP,MATCH($A7,November!$A:$A,0)),0)+IFERROR(INDEX(December!$AQ:$AQ,MATCH($A7,December!$A:$A,0)),0) -> 195.5 | V7: =IFERROR(INDEX(January!$AJ:$AJ,MATCH($A7,January!$A:$A,0)),0)+IFERROR(INDEX(February!$AG:$AG,MATCH($A7,February!$A:$A,0)),0)+IFERROR(INDEX(March!$AJ:$AJ,MATCH($A7,March!$A:$A,0)),0)+IFERROR(INDEX(April!$AI:$AI,MATCH($A7,April!$A:$A,0)),0)+IFERROR(INDEX(May!$AJ:$AJ,MATCH($A7,May!$A:$A,0)),0)+IFERROR(INDEX(June!$AI:$AI,MATCH($A7,June!$A:$A,0)),0)+IFERROR(INDEX(July!$AJ:$AJ,MATCH($A7,July!$A:$A,0)),0)+IFERROR(INDEX(August!$AJ:$AJ,MATCH($A7,August!$A:$A,0)),0)+IFERROR(INDEX(September!$AI:$AI,MATCH($A7,September!$A:$A,0)),0)+IFERROR(INDEX(October!$AJ:$AJ,MATCH($A7,October!$A:$A,0)),0)+IFERROR(INDEX(November!$AI:$AI,MATCH($A7,November!$A:$A,0)),0)+IFERROR(INDEX(December!$AJ:$AJ,MATCH($A7,December!$A:$A,0)),0) -> 83 | W7: =IFERROR(INDEX(January!$AO:$AO,MATCH($A7,January!$A:$A,0)),0)+IFERROR(INDEX(February!$AL:$AL,MATCH($A7,February!$A:$A,0)),0)+IFERROR(INDEX(March!$AO:$AO,MATCH($A7,March!$A:$A,0)),0)+IFERROR(INDEX(April!$AN:$AN,MATCH($A7,April!$A:$A,0)),0)+IFERROR(INDEX(May!$AO:$AO,MATCH($A7,May!$A:$A,0)),0)+IFERROR(INDEX(June!$AN:$AN,MATCH($A7,June!$A:$A,0)),0)+IFERROR(INDEX(July!$AO:$AO,MATCH($A7,July!$A:$A,0)),0)+IFERROR(INDEX(August!$AO:$AO,MATCH($A7,August!$A:$A,0)),0)+IFERROR(INDEX(September!$AN:$AN,MATCH($A7,September!$A:$A,0)),0)+IFERROR(INDEX(October!$AO:$AO,MATCH($A7,October!$A:$A,0)),0)+IFERROR(INDEX(November!$AN:$AN,MATCH($A7,November!$A:$A,0)),0)+IFERROR(INDEX(December!$AO:$AO,MATCH($A7,December!$A:$A,0)),0) -> 16 | X7: =W7/2 -> 8 | Y7: =(IFERROR(INDEX(January!$AL:$AL,MATCH($A7,January!$A:$A,0)),0)+IFERROR(INDEX(February!$AI:$AI,MATCH($A7,February!$A:$A,0)),0)+IFERROR(INDEX(March!$AL:$AL,MATCH($A7,March!$A:$A,0)),0)+IFERROR(INDEX(April!$AK:$AK,MATCH($A7,April!$A:$A,0)),0)+IFERROR(INDEX(May!$AL:$AL,MATCH($A7,May!$A:$A,0)),0)+IFERROR(INDEX(June!$AK:$AK,MATCH($A7,June!$A:$A,0)),0)+IFERROR(INDEX(July!$AL:$AL,MATCH($A7,July!$A:$A,0)),0)+IFERROR(INDEX(August!$AL:$AL,MATCH($A7,August!$A:$A,0)),0)+IFERROR(INDEX(September!$AK:$AK,MATCH($A7,September!$A:$A,0)),0)+IFERROR(INDEX(October!$AL:$AL,MATCH($A7,October!$A:$A,0)),0)+IFERROR(INDEX(November!$AK:$AK,MATCH($A7,November!$A:$A,0)),0)+IFERROR(INDEX(December!$AL:$AL,MATCH($A7,December!$A:$A,0)),0))*0.5 -> 9.5 | Z7: =IFERROR(INDEX(January!$AK:$AK,MATCH($A7,January!$A:$A,0)),0)+IFERROR(INDEX(February!$AH:$AH,MATCH($A7,February!$A:$A,0)),0)+IFERROR(INDEX(March!$AK:$AK,MATCH($A7,March!$A:$A,0)),0)+IFERROR(INDEX(April!$AJ:$AJ,MATCH($A7,April!$A:$A,0)),0)+IFERROR(INDEX(May!$AK:$AK,MATCH($A7,May!$A:$A,0)),0)+IFERROR(INDEX(June!$AJ:$AJ,MATCH($A7,June!$A:$A,0)),0)+IFERROR(INDEX(July!$AK:$AK,MATCH($A7,July!$A:$A,0)),0)+IFERROR(INDEX(August!$AK:$AK,MATCH($A7,August!$A:$A,0)),0)+IFERROR(INDEX(September!$AJ:$AJ,MATCH($A7,September!$A:$A,0)),0)+IFERROR(INDEX(October!$AK:$AK,MATCH($A7,October!$A:$A,0)),0)+IFERROR(INDEX(November!$AJ:$AJ,MATCH($A7,November!$A:$A,0)),0)+IFERROR(INDEX(December!$AK:$AK,MATCH($A7,December!$A:$A,0)),0) -> 16 | AA7: =Y7+Z7 -> 25.5 | AB7: 17 | AC7: =AA7+IF(AB7="",0,AB7) -> 42.5 | AE7: =AC7-IF(AD7="",0,AD7) -> 42.5
A8: 207 | B8: NSABIMANA ABIKUNDA Irene | C8: ADMN | D8: 23 | E8: 23 | F8: 24 | G8: 22 | H8: 22 | I8: 17 | J8: 9 | K8: 23 | L8: 26 | M8: 23 | N8: 14 | O8: 9 | P8: =IFERROR(INDEX(January!$AI:$AI,MATCH($A8,January!$A:$A,0)),0)+IFERROR(INDEX(February!$AF:$AF,MATCH($A8,February!$A:$A,0)),0)+IFERROR(INDEX(March!$AI:$AI,MATCH($A8,March!$A:$A,0)),0)+IFERROR(INDEX(April!$AH:$AH,MATCH($A8,April!$A:$A,0)),0)+IFERROR(INDEX(May!$AI:$AI,MATCH($A8,May!$A:$A,0)),0)+IFERROR(INDEX(June!$AH:$AH,MATCH($A8,June!$A:$A,0)),0)+IFERROR(INDEX(July!$AI:$AI,MATCH($A8,July!$A:$A,0)),0)+IFERROR(INDEX(August!$AI:$AI,MATCH($A8,August!$A:$A,0)),0)+IFERROR(INDEX(September!$AH:$AH,MATCH($A8,September!$A:$A,0)),0)+IFERROR(INDEX(October!$AI:$AI,MATCH($A8,October!$A:$A,0)),0)+IFERROR(INDEX(November!$AH:$AH,MATCH($A8,November!$A:$A,0)),0)+IFERROR(INDEX(December!$AI:$AI,MATCH($A8,December!$A:$A,0)),0) -> 187 | Q8: =IFERROR(INDEX(January!$AJ:$AJ,MATCH($A8,January!$A:$A,0)),0)+IFERROR(INDEX(February!$AG:$AG,MATCH($A8,February!$A:$A,0)),0)+IFERROR(INDEX(March!$AJ:$AJ,MATCH($A8,March!$A:$A,0)),0)+IFERROR(INDEX(April!$AI:$AI,MATCH($A8,April!$A:$A,0)),0)+IFERROR(INDEX(May!$AJ:$AJ,MATCH($A8,May!$A:$A,0)),0)+IFERROR(INDEX(June!$AI:$AI,MATCH($A8,June!$A:$A,0)),0)+IFERROR(INDEX(July!$AJ:$AJ,MATCH($A8,July!$A:$A,0)),0)+IFERROR(INDEX(August!$AJ:$AJ,MATCH($A8,August!$A:$A,0)),0)+IFERROR(INDEX(September!$AI:$AI,MATCH($A8,September!$A:$A,0)),0)+IFERROR(INDEX(October!$AJ:$AJ,MATCH($A8,October!$A:$A,0)),0)+IFERROR(INDEX(November!$AI:$AI,MATCH($A8,November!$A:$A,0)),0)+IFERROR(INDEX(December!$AJ:$AJ,MATCH($A8,December!$A:$A,0)),0) -> 74 | R8: =IFERROR(INDEX(January!$AK:$AK,MATCH($A8,January!$A:$A,0)),0)+IFERROR(INDEX(February!$AH:$AH,MATCH($A8,February!$A:$A,0)),0)+IFERROR(INDEX(March!$AK:$AK,MATCH($A8,March!$A:$A,0)),0)+IFERROR(INDEX(April!$AJ:$AJ,MATCH($A8,April!$A:$A,0)),0)+IFERROR(INDEX(May!$AK:$AK,MATCH($A8,May!$A:$A,0)),0)+IFERROR(INDEX(June!$AJ:$AJ,MATCH($A8,June!$A:$A,0)),0)+IFERROR(INDEX(July!$AK:$AK,MATCH($A8,July!$A:$A,0)),0)+IFERROR(INDEX(August!$AK:$AK,MATCH($A8,August!$A:$A,0)),0)+IFERROR(INDEX(September!$AJ:$AJ,MATCH($A8,September!$A:$A,0)),0)+IFERROR(INDEX(October!$AK:$AK,MATCH($A8,October!$A:$A,0)),0)+IFERROR(INDEX(November!$AJ:$AJ,MATCH($A8,November!$A:$A,0)),0)+IFERROR(INDEX(December!$AK:$AK,MATCH($A8,December!$A:$A,0)),0) -> 24 | S8: =IF((P8+Q8)=0,"",P8/(P8+Q8)) -> 0.7164751 | U8: =IFERROR(INDEX(January!$AQ:$AQ,MATCH($A8,January!$A:$A,0)),0)+IFERROR(INDEX(February!$AN:$AN,MATCH($A8,February!$A:$A,0)),0)+IFERROR(INDEX(March!$AQ:$AQ,MATCH($A8,March!$A:$A,0)),0)+IFERROR(INDEX(April!$AP:$AP,MATCH($A8,April!$A:$A,0)),0)+IFERROR(INDEX(May!$AQ:$AQ,MATCH($A8,May!$A:$A,0)),0)+IFERROR(INDEX(June!$AP:$AP,MATCH($A8,June!$A:$A,0)),0)+IFERROR(INDEX(July!$AQ:$AQ,MATCH($A8,July!$A:$A,0)),0)+IFERROR(INDEX(August!$AQ:$AQ,MATCH($A8,August!$A:$A,0)),0)+IFERROR(INDEX(September!$AP:$AP,MATCH($A8,September!$A:$A,0)),0)+IFERROR(INDEX(October!$AQ:$AQ,MATCH($A8,October!$A:$A,0)),0)+IFERROR(INDEX(November!$AP:$AP,MATCH($A8,November!$A:$A,0)),0)+IFERROR(INDEX(December!$AQ:$AQ,MATCH($A8,December!$A:$A,0)),0) -> 218 | V8: =IFERROR(INDEX(January!$AJ:$AJ,MATCH($A8,January!$A:$A,0)),0)+IFERROR(INDEX(February!$AG:$AG,MATCH($A8,February!$A:$A,0)),0)+IFERROR(INDEX(March!$AJ:$AJ,MATCH($A8,March!$A:$A,0)),0)+IFERROR(INDEX(April!$AI:$AI,MATCH($A8,April!$A:$A,0)),0)+IFERROR(INDEX(May!$AJ:$AJ,MATCH($A8,May!$A:$A,0)),0)+IFERROR(INDEX(June!$AI:$AI,MATCH($A8,June!$A:$A,0)),0)+IFERROR(INDEX(July!$AJ:$AJ,MATCH($A8,July!$A:$A,0)),0)+IFERROR(INDEX(August!$AJ:$AJ,MATCH($A8,August!$A:$A,0)),0)+IFERROR(INDEX(September!$AI:$AI,MATCH($A8,September!$A:$A,0)),0)+IFERROR(INDEX(October!$AJ:$AJ,MATCH($A8,October!$A:$A,0)),0)+IFERROR(INDEX(November!$AI:$AI,MATCH($A8,November!$A:$A,0)),0)+IFERROR(INDEX(December!$AJ:$AJ,MATCH($A8,December!$A:$A,0)),0) -> 74 | W8: =IFERROR(INDEX(January!$AO:$AO,MATCH($A8,January!$A:$A,0)),0)+IFERROR(INDEX(February!$AL:$AL,MATCH($A8,February!$A:$A,0)),0)+IFERROR(INDEX(March!$AO:$AO,MATCH($A8,March!$A:$A,0)),0)+IFERROR(INDEX(April!$AN:$AN,MATCH($A8,April!$A:$A,0)),0)+IFERROR(INDEX(May!$AO:$AO,MATCH($A8,May!$A:$A,0)),0)+IFERROR(INDEX(June!$AN:$AN,MATCH($A8,June!$A:$A,0)),0)+IFERROR(INDEX(July!$AO:$AO,MATCH($A8,July!$A:$A,0)),0)+IFERROR(INDEX(August!$AO:$AO,MATCH($A8,August!$A:$A,0)),0)+IFERROR(INDEX(September!$AN:$AN,MATCH($A8,September!$A:$A,0)),0)+IFERROR(INDEX(October!$AO:$AO,MATCH($A8,October!$A:$A,0)),0)+IFERROR(INDEX(November!$AN:$AN,MATCH($A8,November!$A:$A,0)),0)+IFERROR(INDEX(December!$AO:$AO,MATCH($A8,December!$A:$A,0)),0) -> 10 | X8: =W8/2 -> 5 | Y8: =(IFERROR(INDEX(January!$AL:$AL,MATCH($A8,January!$A:$A,0)),0)+IFERROR(INDEX(February!$AI:$AI,MATCH($A8,February!$A:$A,0)),0)+IFERROR(INDEX(March!$AL:$AL,MATCH($A8,March!$A:$A,0)),0)+IFERROR(INDEX(April!$AK:$AK,MATCH($A8,April!$A:$A,0)),0)+IFERROR(INDEX(May!$AL:$AL,MATCH($A8,May!$A:$A,0)),0)+IFERROR(INDEX(June!$AK:$AK,MATCH($A8,June!$A:$A,0)),0)+IFERROR(INDEX(July!$AL:$AL,MATCH($A8,July!$A:$A,0)),0)+IFERROR(INDEX(August!$AL:$AL,MATCH($A8,August!$A:$A,0)),0)+IFERROR(INDEX(September!$AK:$AK,MATCH($A8,September!$A:$A,0)),0)+IFERROR(INDEX(October!$AL:$AL,MATCH($A8,October!$A:$A,0)),0)+IFERROR(INDEX(November!$AK:$AK,MATCH($A8,November!$A:$A,0)),0)+IFERROR(INDEX(December!$AL:$AL,MATCH($A8,December!$A:$A,0)),0))*0.5 -> 12 | Z8: =IFERROR(INDEX(January!$AK:$AK,MATCH($A8,January!$A:$A,0)),0)+IFERROR(INDEX(February!$AH:$AH,MATCH($A8,February!$A:$A,0)),0)+IFERROR(INDEX(March!$AK:$AK,MATCH($A8,March!$A:$A,0)),0)+IFERROR(INDEX(April!$AJ:$AJ,MATCH($A8,April!$A:$A,0)),0)+IFERROR(INDEX(May!$AK:$AK,MATCH($A8,May!$A:$A,0)),0)+IFERROR(INDEX(June!$AJ:$AJ,MATCH($A8,June!$A:$A,0)),0)+IFERROR(INDEX(July!$AK:$AK,MATCH($A8,July!$A:$A,0)),0)+IFERROR(INDEX(August!$AK:$AK,MATCH($A8,August!$A:$A,0)),0)+IFERROR(INDEX(September!$AJ:$AJ,MATCH($A8,September!$A:$A,0)),0)+IFERROR(INDEX(October!$AK:$AK,MATCH($A8,October!$A:$A,0)),0)+IFERROR(INDEX(November!$AJ:$AJ,MATCH($A8,November!$A:$A,0)),0)+IFERROR(INDEX(December!$AK:$AK,MATCH($A8,December!$A:$A,0)),0) -> 24 | AA8: =Y8+Z8 -> 36 | AB8: 17 | AC8: =AA8+IF(AB8="",0,AB8) -> 53 | AE8: =AC8-IF(AD8="",0,AD8) -> 53
A9: 211 | B9: HAKIZIMANA DIOGENE | C9: ADMN | D9: 10 | E9: 20 | F9: 24 | G9: 3 | H9: 15 | I9: 22 | J9: 22 | K9: 22 | L9: 26 | M9: 20 | N9: 18 | O9: 18 | P9: =IFERROR(INDEX(January!$AI:$AI,MATCH($A9,January!$A:$A,0)),0)+IFERROR(INDEX(February!$AF:$AF,MATCH($A9,February!$A:$A,0)),0)+IFERROR(INDEX(March!$AI:$AI,MATCH($A9,March!$A:$A,0)),0)+IFERROR(INDEX(April!$AH:$AH,MATCH($A9,April!$A:$A,0)),0)+IFERROR(INDEX(May!$AI:$AI,MATCH($A9,May!$A:$A,0)),0)+IFERROR(INDEX(June!$AH:$AH,MATCH($A9,June!$A:$A,0)),0)+IFERROR(INDEX(July!$AI:$AI,MATCH($A9,July!$A:$A,0)),0)+IFERROR(INDEX(August!$AI:$AI,MATCH($A9,August!$A:$A,0)),0)+IFERROR(INDEX(September!$AH:$AH,MATCH($A9,September!$A:$A,0)),0)+IFERROR(INDEX(October!$AI:$AI,MATCH($A9,October!$A:$A,0)),0)+IFERROR(INDEX(November!$AH:$AH,MATCH($A9,November!$A:$A,0)),0)+IFERROR(INDEX(December!$AI:$AI,MATCH($A9,December!$A:$A,0)),0) -> 188 | Q9: =IFERROR(INDEX(January!$AJ:$AJ,MATCH($A9,January!$A:$A,0)),0)+IFERROR(INDEX(February!$AG:$AG,MATCH($A9,February!$A:$A,0)),0)+IFERROR(INDEX(March!$AJ:$AJ,MATCH($A9,March!$A:$A,0)),0)+IFERROR(INDEX(April!$AI:$AI,MATCH($A9,April!$A:$A,0)),0)+IFERROR(INDEX(May!$AJ:$AJ,MATCH($A9,May!$A:$A,0)),0)+IFERROR(INDEX(June!$AI:$AI,MATCH($A9,June!$A:$A,0)),0)+IFERROR(INDEX(July!$AJ:$AJ,MATCH($A9,July!$A:$A,0)),0)+IFERROR(INDEX(August!$AJ:$AJ,MATCH($A9,August!$A:$A,0)),0)+IFERROR(INDEX(September!$AI:$AI,MATCH($A9,September!$A:$A,0)),0)+IFERROR(INDEX(October!$AJ:$AJ,MATCH($A9,October!$A:$A,0)),0)+IFERROR(INDEX(November!$AI:$AI,MATCH($A9,November!$A:$A,0)),0)+IFERROR(INDEX(December!$AJ:$AJ,MATCH($A9,December!$A:$A,0)),0) -> 73 | R9: =IFERROR(INDEX(January!$AK:$AK,MATCH($A9,January!$A:$A,0)),0)+IFERROR(INDEX(February!$AH:$AH,MATCH($A9,February!$A:$A,0)),0)+IFERROR(INDEX(March!$AK:$AK,MATCH($A9,March!$A:$A,0)),0)+IFERROR(INDEX(April!$AJ:$AJ,MATCH($A9,April!$A:$A,0)),0)+IFERROR(INDEX(May!$AK:$AK,MATCH($A9,May!$A:$A,0)),0)+IFERROR(INDEX(June!$AJ:$AJ,MATCH($A9,June!$A:$A,0)),0)+IFERROR(INDEX(July!$AK:$AK,MATCH($A9,July!$A:$A,0)),0)+IFERROR(INDEX(August!$AK:$AK,MATCH($A9,August!$A:$A,0)),0)+IFERROR(INDEX(September!$AJ:$AJ,MATCH($A9,September!$A:$A,0)),0)+IFERROR(INDEX(October!$AK:$AK,MATCH($A9,October!$A:$A,0)),0)+IFERROR(INDEX(November!$AJ:$AJ,MATCH($A9,November!$A:$A,0)),0)+IFERROR(INDEX(December!$AK:$AK,MATCH($A9,December!$A:$A,0)),0) -> 16 | S9: =IF((P9+Q9)=0,"",P9/(P9+Q9)) -> 0.72030651 | U9: =IFERROR(INDEX(January!$AQ:$AQ,MATCH($A9,January!$A:$A,0)),0)+IFERROR(INDEX(February!$AN:$AN,MATCH($A9,February!$A:$A,0)),0)+IFERROR(INDEX(March!$AQ:$AQ,MATCH($A9,March!$A:$A,0)),0)+IFERROR(INDEX(April!$AP:$AP,MATCH($A9,April!$A:$A,0)),0)+IFERROR(INDEX(May!$AQ:$AQ,MATCH($A9,May!$A:$A,0)),0)+IFERROR(INDEX(June!$AP:$AP,MATCH($A9,June!$A:$A,0)),0)+IFERROR(INDEX(July!$AQ:$AQ,MATCH($A9,July!$A:$A,0)),0)+IFERROR(INDEX(August!$AQ:$AQ,MATCH($A9,August!$A:$A,0)),0)+IFERROR(INDEX(September!$AP:$AP,MATCH($A9,September!$A:$A,0)),0)+IFERROR(INDEX(October!$AQ:$AQ,MATCH($A9,October!$A:$A,0)),0)+IFERROR(INDEX(November!$AP:$AP,MATCH($A9,November!$A:$A,0)),0)+IFERROR(INDEX(December!$AQ:$AQ,MATCH($A9,December!$A:$A,0)),0) -> 203.5 | V9: =IFERROR(INDEX(January!$AJ:$AJ,MATCH($A9,January!$A:$A,0)),0)+IFERROR(INDEX(February!$AG:$AG,MATCH($A9,February!$A:$A,0)),0)+IFERROR(INDEX(March!$AJ:$AJ,MATCH($A9,March!$A:$A,0)),0)+IFERROR(INDEX(April!$AI:$AI,MATCH($A9,April!$A:$A,0)),0)+IFERROR(INDEX(May!$AJ:$AJ,MATCH($A9,May!$A:$A,0)),0)+IFERROR(INDEX(June!$AI:$AI,MATCH($A9,June!$A:$A,0)),0)+IFERROR(INDEX(July!$AJ:$AJ,MATCH($A9,July!$A:$A,0)),0)+IFERROR(INDEX(August!$AJ:$AJ,MATCH($A9,August!$A:$A,0)),0)+IFERROR(INDEX(September!$AI:$AI,MATCH($A9,September!$A:$A,0)),0)+IFERROR(INDEX(October!$AJ:$AJ,MATCH($A9,October!$A:$A,0)),0)+IFERROR(INDEX(November!$AI:$AI,MATCH($A9,November!$A:$A,0)),0)+IFERROR(INDEX(December!$AJ:$AJ,MATCH($A9,December!$A:$A,0)),0) -> 73 | W9: =IFERROR(INDEX(January!$AO:$AO,MATCH($A9,January!$A:$A,0)),0)+IFERROR(INDEX(February!$AL:$AL,MATCH($A9,February!$A:$A,0)),0)+IFERROR(INDEX(March!$AO:$AO,MATCH($A9,March!$A:$A,0)),0)+IFERROR(INDEX(April!$AN:$AN,MATCH($A9,April!$A:$A,0)),0)+IFERROR(INDEX(May!$AO:$AO,MATCH($A9,May!$A:$A,0)),0)+IFERROR(INDEX(June!$AN:$AN,MATCH($A9,June!$A:$A,0)),0)+IFERROR(INDEX(July!$AO:$AO,MATCH($A9,July!$A:$A,0)),0)+IFERROR(INDEX(August!$AO:$AO,MATCH($A9,August!$A:$A,0)),0)+IFERROR(INDEX(September!$AN:$AN,MATCH($A9,September!$A:$A,0)),0)+IFERROR(INDEX(October!$AO:$AO,MATCH($A9,October!$A:$A,0)),0)+IFERROR(INDEX(November!$AN:$AN,MATCH($A9,November!$A:$A,0)),0)+IFERROR(INDEX(December!$AO:$AO,MATCH($A9,December!$A:$A,0)),0) -> 17 | X9: =W9/2 -> 8.5 | Y9: =(IFERROR(INDEX(January!$AL:$AL,MATCH($A9,January!$A:$A,0)),0)+IFERROR(INDEX(February!$AI:$AI,MATCH($A9,February!$A:$A,0)),0)+IFERROR(INDEX(March!$AL:$AL,MATCH($A9,March!$A:$A,0)),0)+IFERROR(INDEX(April!$AK:$AK,MATCH($A9,April!$A:$A,0)),0)+IFERROR(INDEX(May!$AL:$AL,MATCH($A9,May!$A:$A,0)),0)+IFERROR(INDEX(June!$AK:$AK,MATCH($A9,June!$A:$A,0)),0)+IFERROR(INDEX(July!$AL:$AL,MATCH($A9,July!$A:$A,0)),0)+IFERROR(INDEX(August!$AL:$AL,MATCH($A9,August!$A:$A,0)),0)+IFERROR(INDEX(September!$AK:$AK,MATCH($A9,September!$A:$A,0)),0)+IFERROR(INDEX(October!$AL:$AL,MATCH($A9,October!$A:$A,0)),0)+IFERROR(INDEX(November!$AK:$AK,MATCH($A9,November!$A:$A,0)),0)+IFERROR(INDEX(December!$AL:$AL,MATCH($A9,December!$A:$A,0)),0))*0.5 -> 8 | Z9: =IFERROR(INDEX(January!$AK:$AK,MATCH($A9,January!$A:$A,0)),0)+IFERROR(INDEX(February!$AH:$AH,MATCH($A9,February!$A:$A,0)),0)+IFERROR(INDEX(March!$AK:$AK,MATCH($A9,March!$A:$A,0)),0)+IFERROR(INDEX(April!$AJ:$AJ,MATCH($A9,April!$A:$A,0)),0)+IFERROR(INDEX(May!$AK:$AK,MATCH($A9,May!$A:$A,0)),0)+IFERROR(INDEX(June!$AJ:$AJ,MATCH($A9,June!$A:$A,0)),0)+IFERROR(INDEX(July!$AK:$AK,MATCH($A9,July!$A:$A,0)),0)+IFERROR(INDEX(August!$AK:$AK,MATCH($A9,August!$A:$A,0)),0)+IFERROR(INDEX(September!$AJ:$AJ,MATCH($A9,September!$A:$A,0)),0)+IFERROR(INDEX(October!$AK:$AK,MATCH($A9,October!$A:$A,0)),0)+IFERROR(INDEX(November!$AJ:$AJ,MATCH($A9,November!$A:$A,0)),0)+IFERROR(INDEX(December!$AK:$AK,MATCH($A9,December!$A:$A,0)),0) -> 16 | AA9: =Y9+Z9 -> 24 | AB9: 17 | AC9: =AA9+IF(AB9="",0,AB9) -> 41 | AE9: =AC9-IF(AD9="",0,AD9) -> 41
A10: 249 | B10: KARIHANZE THEMISTOCLESS | C10: ADMN | D10: 22 | E10: 22 | F10: 14 | G10: 15 | H10: 22 | I10: 23 | J10: 25 | K10: 19 | L10: 25 | M10: 27 | N10: 10 | O10: 5 | P10: =IFERROR(INDEX(January!$AI:$AI,MATCH($A10,January!$A:$A,0)),0)+IFERROR(INDEX(February!$AF:$AF,MATCH($A10,February!$A:$A,0)),0)+IFERROR(INDEX(March!$AI:$AI,MATCH($A10,March!$A:$A,0)),0)+IFERROR(INDEX(April!$AH:$AH,MATCH($A10,April!$A:$A,0)),0)+IFERROR(INDEX(May!$AI:$AI,MATCH($A10,May!$A:$A,0)),0)+IFERROR(INDEX(June!$AH:$AH,MATCH($A10,June!$A:$A,0)),0)+IFERROR(INDEX(July!$AI:$AI,MATCH($A10,July!$A:$A,0)),0)+IFERROR(INDEX(August!$AI:$AI,MATCH($A10,August!$A:$A,0)),0)+IFERROR(INDEX(September!$AH:$AH,MATCH($A10,September!$A:$A,0)),0)+IFERROR(INDEX(October!$AI:$AI,MATCH($A10,October!$A:$A,0)),0)+IFERROR(INDEX(November!$AH:$AH,MATCH($A10,November!$A:$A,0)),0)+IFERROR(INDEX(December!$AI:$AI,MATCH($A10,December!$A:$A,0)),0) -> 185 | Q10: =IFERROR(INDEX(January!$AJ:$AJ,MATCH($A10,January!$A:$A,0)),0)+IFERROR(INDEX(February!$AG:$AG,MATCH($A10,February!$A:$A,0)),0)+IFERROR(INDEX(March!$AJ:$AJ,MATCH($A10,March!$A:$A,0)),0)+IFERROR(INDEX(April!$AI:$AI,MATCH($A10,April!$A:$A,0)),0)+IFERROR(INDEX(May!$AJ:$AJ,MATCH($A10,May!$A:$A,0)),0)+IFERROR(INDEX(June!$AI:$AI,MATCH($A10,June!$A:$A,0)),0)+IFERROR(INDEX(July!$AJ:$AJ,MATCH($A10,July!$A:$A,0)),0)+IFERROR(INDEX(August!$AJ:$AJ,MATCH($A10,August!$A:$A,0)),0)+IFERROR(INDEX(September!$AI:$AI,MATCH($A10,September!$A:$A,0)),0)+IFERROR(INDEX(October!$AJ:$AJ,MATCH($A10,October!$A:$A,0)),0)+IFERROR(INDEX(November!$AI:$AI,MATCH($A10,November!$A:$A,0)),0)+IFERROR(INDEX(December!$AJ:$AJ,MATCH($A10,December!$A:$A,0)),0) -> 76 | R10: =IFERROR(INDEX(January!$AK:$AK,MATCH($A10,January!$A:$A,0)),0)+IFERROR(INDEX(February!$AH:$AH,MATCH($A10,February!$A:$A,0)),0)+IFERROR(INDEX(March!$AK:$AK,MATCH($A10,March!$A:$A,0)),0)+IFERROR(INDEX(April!$AJ:$AJ,MATCH($A10,April!$A:$A,0)),0)+IFERROR(INDEX(May!$AK:$AK,MATCH($A10,May!$A:$A,0)),0)+IFERROR(INDEX(June!$AJ:$AJ,MATCH($A10,June!$A:$A,0)),0)+IFERROR(INDEX(July!$AK:$AK,MATCH($A10,July!$A:$A,0)),0)+IFERROR(INDEX(August!$AK:$AK,MATCH($A10,August!$A:$A,0)),0)+IFERROR(INDEX(September!$AJ:$AJ,MATCH($A10,September!$A:$A,0)),0)+IFERROR(INDEX(October!$AK:$AK,MATCH($A10,October!$A:$A,0)),0)+IFERROR(INDEX(November!$AJ:$AJ,MATCH($A10,November!$A:$A,0)),0)+IFERROR(INDEX(December!$AK:$AK,MATCH($A10,December!$A:$A,0)),0) -> 21 | S10: =IF((P10+Q10)=0,"",P10/(P10+Q10)) -> 0.70881226 | U10: =IFERROR(INDEX(January!$AQ:$AQ,MATCH($A10,January!$A:$A,0)),0)+IFERROR(INDEX(February!$AN:$AN,MATCH($A10,February!$A:$A,0)),0)+IFERROR(INDEX(March!$AQ:$AQ,MATCH($A10,March!$A:$A,0)),0)+IFERROR(INDEX(April!$AP:$AP,MATCH($A10,April!$A:$A,0)),0)+IFERROR(INDEX(May!$AQ:$AQ,MATCH($A10,May!$A:$A,0)),0)+IFERROR(INDEX(June!$AP:$AP,MATCH($A10,June!$A:$A,0)),0)+IFERROR(INDEX(July!$AQ:$AQ,MATCH($A10,July!$A:$A,0)),0)+IFERROR(INDEX(August!$AQ:$AQ,MATCH($A10,August!$A:$A,0)),0)+IFERROR(INDEX(September!$AP:$AP,MATCH($A10,September!$A:$A,0)),0)+IFERROR(INDEX(October!$AQ:$AQ,MATCH($A10,October!$A:$A,0)),0)+IFERROR(INDEX(November!$AP:$AP,MATCH($A10,November!$A:$A,0)),0)+IFERROR(INDEX(December!$AQ:$AQ,MATCH($A10,December!$A:$A,0)),0) -> 210.5 | V10: =IFERROR(INDEX(January!$AJ:$AJ,MATCH($A10,January!$A:$A,0)),0)+IFERROR(INDEX(February!$AG:$AG,MATCH($A10,February!$A:$A,0)),0)+IFERROR(INDEX(March!$AJ:$AJ,MATCH($A10,March!$A:$A,0)),0)+IFERROR(INDEX(April!$AI:$AI,MATCH($A10,April!$A:$A,0)),0)+IFERROR(INDEX(May!$AJ:$AJ,MATCH($A10,May!$A:$A,0)),0)+IFERROR(INDEX(June!$AI:$AI,MATCH($A10,June!$A:$A,0)),0)+IFERROR(INDEX(July!$AJ:$AJ,MATCH($A10,July!$A:$A,0)),0)+IFERROR(INDEX(August!$AJ:$AJ,MATCH($A10,August!$A:$A,0)),0)+IFERROR(INDEX(September!$AI:$AI,MATCH($A10,September!$A:$A,0)),0)+IFERROR(INDEX(October!$AJ:$AJ,MATCH($A10,October!$A:$A,0)),0)+IFERROR(INDEX(November!$AI:$AI,MATCH($A10,November!$A:$A,0)),0)+IFERROR(INDEX(December!$AJ:$AJ,MATCH($A10,December!$A:$A,0)),0) -> 76 | W10: =IFERROR(INDEX(January!$AO:$AO,MATCH($A10,January!$A:$A,0)),0)+IFERROR(INDEX(February!$AL:$AL,MATCH($A10,February!$A:$A,0)),0)+IFERROR(INDEX(March!$AO:$AO,MATCH($A10,March!$A:$A,0)),0)+IFERROR(INDEX(April!$AN:$AN,MATCH($A10,April!$A:$A,0)),0)+IFERROR(INDEX(May!$AO:$AO,MATCH($A10,May!$A:$A,0)),0)+IFERROR(INDEX(June!$AN:$AN,MATCH($A10,June!$A:$A,0)),0)+IFERROR(INDEX(July!$AO:$AO,MATCH($A10,July!$A:$A,0)),0)+IFERROR(INDEX(August!$AO:$AO,MATCH($A10,August!$A:$A,0)),0)+IFERROR(INDEX(September!$AN:$AN,MATCH($A10,September!$A:$A,0)),0)+IFERROR(INDEX(October!$AO:$AO,MATCH($A10,October!$A:$A,0)),0)+IFERROR(INDEX(November!$AN:$AN,MATCH($A10,November!$A:$A,0)),0)+IFERROR(INDEX(December!$AO:$AO,MATCH($A10,December!$A:$A,0)),0) -> 14 | X10: =W10/2 -> 7 | Y10: =(IFERROR(INDEX(January!$AL:$AL,MATCH($A10,January!$A:$A,0)),0)+IFERROR(INDEX(February!$AI:$AI,MATCH($A10,February!$A:$A,0)),0)+IFERROR(INDEX(March!$AL:$AL,MATCH($A10,March!$A:$A,0)),0)+IFERROR(INDEX(April!$AK:$AK,MATCH($A10,April!$A:$A,0)),0)+IFERROR(INDEX(May!$AL:$AL,MATCH($A10,May!$A:$A,0)),0)+IFERROR(INDEX(June!$AK:$AK,MATCH($A10,June!$A:$A,0)),0)+IFERROR(INDEX(July!$AL:$AL,MATCH($A10,July!$A:$A,0)),0)+IFERROR(INDEX(August!$AL:$AL,MATCH($A10,August!$A:$A,0)),0)+IFERROR(INDEX(September!$AK:$AK,MATCH($A10,September!$A:$A,0)),0)+IFERROR(INDEX(October!$AL:$AL,MATCH($A10,October!$A:$A,0)),0)+IFERROR(INDEX(November!$AK:$AK,MATCH($A10,November!$A:$A,0)),0)+IFERROR(INDEX(December!$AL:$AL,MATCH($A10,December!$A:$A,0)),0))*0.5 -> 11.5 | Z10: =IFERROR(INDEX(January!$AK:$AK,MATCH($A10,January!$A:$A,0)),0)+IFERROR(INDEX(February!$AH:$AH,MATCH($A10,February!$A:$A,0)),0)+IFERROR(INDEX(March!$AK:$AK,MATCH($A10,March!$A:$A,0)),0)+IFERROR(INDEX(April!$AJ:$AJ,MATCH($A10,April!$A:$A,0)),0)+IFERROR(INDEX(May!$AK:$AK,MATCH($A10,May!$A:$A,0)),0)+IFERROR(INDEX(June!$AJ:$AJ,MATCH($A10,June!$A:$A,0)),0)+IFERROR(INDEX(July!$AK:$AK,MATCH($A10,July!$A:$A,0)),0)+IFERROR(INDEX(August!$AK:$AK,MATCH($A10,August!$A:$A,0)),0)+IFERROR(INDEX(September!$AJ:$AJ,MATCH($A10,September!$A:$A,0)),0)+IFERROR(INDEX(October!$AK:$AK,MATCH($A10,October!$A:$A,0)),0)+IFERROR(INDEX(November!$AJ:$AJ,MATCH($A10,November!$A:$A,0)),0)+IFERROR(INDEX(December!$AK:$AK,MATCH($A10,December!$A:$A,0)),0) -> 21 | AA10: =Y10+Z10 -> 32.5 | AB10: 17 | AC10: =AA10+IF(AB10="",0,AB10) -> 49.5 | AE10: =AC10-IF(AD10="",0,AD10) -> 49.5
A11: 251 | B11: UKWISHAKA JEAN AIME | C11: ADMN | D11: 24 | E11: 21 | F11: 25 | G11: 26 | H11: 4 | I11: 22 | J11: 25 | K11: 27 | L11: 28 | M11: 12 | N11: 21 | O11: 5 | P11: =IFERROR(INDEX(January!$AI:$AI,MATCH($A11,January!$A:$A,0)),0)+IFERROR(INDEX(February!$AF:$AF,MATCH($A11,February!$A:$A,0)),0)+IFERROR(INDEX(March!$AI:$AI,MATCH($A11,March!$A:$A,0)),0)+IFERROR(INDEX(April!$AH:$AH,MATCH($A11,April!$A:$A,0)),0)+IFERROR(INDEX(May!$AI:$AI,MATCH($A11,May!$A:$A,0)),0)+IFERROR(INDEX(June!$AH:$AH,MATCH($A11,June!$A:$A,0)),0)+IFERROR(INDEX(July!$AI:$AI,MATCH($A11,July!$A:$A,0)),0)+IFERROR(INDEX(August!$AI:$AI,MATCH($A11,August!$A:$A,0)),0)+IFERROR(INDEX(September!$AH:$AH,MATCH($A11,September!$A:$A,0)),0)+IFERROR(INDEX(October!$AI:$AI,MATCH($A11,October!$A:$A,0)),0)+IFERROR(INDEX(November!$AH:$AH,MATCH($A11,November!$A:$A,0)),0)+IFERROR(INDEX(December!$AI:$AI,MATCH($A11,December!$A:$A,0)),0) -> 189 | Q11: =IFERROR(INDEX(January!$AJ:$AJ,MATCH($A11,January!$A:$A,0)),0)+IFERROR(INDEX(February!$AG:$AG,MATCH($A11,February!$A:$A,0)),0)+IFERROR(INDEX(March!$AJ:$AJ,MATCH($A11,March!$A:$A,0)),0)+IFERROR(INDEX(April!$AI:$AI,MATCH($A11,April!$A:$A,0)),0)+IFERROR(INDEX(May!$AJ:$AJ,MATCH($A11,May!$A:$A,0)),0)+IFERROR(INDEX(June!$AI:$AI,MATCH($A11,June!$A:$A,0)),0)+IFERROR(INDEX(July!$AJ:$AJ,MATCH($A11,July!$A:$A,0)),0)+IFERROR(INDEX(August!$AJ:$AJ,MATCH($A11,August!$A:$A,0)),0)+IFERROR(INDEX(September!$AI:$AI,MATCH($A11,September!$A:$A,0)),0)+IFERROR(INDEX(October!$AJ:$AJ,MATCH($A11,October!$A:$A,0)),0)+IFERROR(INDEX(November!$AI:$AI,MATCH($A11,November!$A:$A,0)),0)+IFERROR(INDEX(December!$AJ:$AJ,MATCH($A11,December!$A:$A,0)),0) -> 72 | R11: =IFERROR(INDEX(January!$AK:$AK,MATCH($A11,January!$A:$A,0)),0)+IFERROR(INDEX(February!$AH:$AH,MATCH($A11,February!$A:$A,0)),0)+IFERROR(INDEX(March!$AK:$AK,MATCH($A11,March!$A:$A,0)),0)+IFERROR(INDEX(April!$AJ:$AJ,MATCH($A11,April!$A:$A,0)),0)+IFERROR(INDEX(May!$AK:$AK,MATCH($A11,May!$A:$A,0)),0)+IFERROR(INDEX(June!$AJ:$AJ,MATCH($A11,June!$A:$A,0)),0)+IFERROR(INDEX(July!$AK:$AK,MATCH($A11,July!$A:$A,0)),0)+IFERROR(INDEX(August!$AK:$AK,MATCH($A11,August!$A:$A,0)),0)+IFERROR(INDEX(September!$AJ:$AJ,MATCH($A11,September!$A:$A,0)),0)+IFERROR(INDEX(October!$AK:$AK,MATCH($A11,October!$A:$A,0)),0)+IFERROR(INDEX(November!$AJ:$AJ,MATCH($A11,November!$A:$A,0)),0)+IFERROR(INDEX(December!$AK:$AK,MATCH($A11,December!$A:$A,0)),0) -> 25 | S11: =IF((P11+Q11)=0,"",P11/(P11+Q11)) -> 0.72413793 | U11: =IFERROR(INDEX(January!$AQ:$AQ,MATCH($A11,January!$A:$A,0)),0)+IFERROR(INDEX(February!$AN:$AN,MATCH($A11,February!$A:$A,0)),0)+IFERROR(INDEX(March!$AQ:$AQ,MATCH($A11,March!$A:$A,0)),0)+IFERROR(INDEX(April!$AP:$AP,MATCH($A11,April!$A:$A,0)),0)+IFERROR(INDEX(May!$AQ:$AQ,MATCH($A11,May!$A:$A,0)),0)+IFERROR(INDEX(June!$AP:$AP,MATCH($A11,June!$A:$A,0)),0)+IFERROR(INDEX(July!$AQ:$AQ,MATCH($A11,July!$A:$A,0)),0)+IFERROR(INDEX(August!$AQ:$AQ,MATCH($A11,August!$A:$A,0)),0)+IFERROR(INDEX(September!$AP:$AP,MATCH($A11,September!$A:$A,0)),0)+IFERROR(INDEX(October!$AQ:$AQ,MATCH($A11,October!$A:$A,0)),0)+IFERROR(INDEX(November!$AP:$AP,MATCH($A11,November!$A:$A,0)),0)+IFERROR(INDEX(December!$AQ:$AQ,MATCH($A11,December!$A:$A,0)),0) -> 221 | V11: =IFERROR(INDEX(January!$AJ:$AJ,MATCH($A11,January!$A:$A,0)),0)+IFERROR(INDEX(February!$AG:$AG,MATCH($A11,February!$A:$A,0)),0)+IFERROR(INDEX(March!$AJ:$AJ,MATCH($A11,March!$A:$A,0)),0)+IFERROR(INDEX(April!$AI:$AI,MATCH($A11,April!$A:$A,0)),0)+IFERROR(INDEX(May!$AJ:$AJ,MATCH($A11,May!$A:$A,0)),0)+IFERROR(INDEX(June!$AI:$AI,MATCH($A11,June!$A:$A,0)),0)+IFERROR(INDEX(July!$AJ:$AJ,MATCH($A11,July!$A:$A,0)),0)+IFERROR(INDEX(August!$AJ:$AJ,MATCH($A11,August!$A:$A,0)),0)+IFERROR(INDEX(September!$AI:$AI,MATCH($A11,September!$A:$A,0)),0)+IFERROR(INDEX(October!$AJ:$AJ,MATCH($A11,October!$A:$A,0)),0)+IFERROR(INDEX(November!$AI:$AI,MATCH($A11,November!$A:$A,0)),0)+IFERROR(INDEX(December!$AJ:$AJ,MATCH($A11,December!$A:$A,0)),0) -> 72 | W11: =IFERROR(INDEX(January!$AO:$AO,MATCH($A11,January!$A:$A,0)),0)+IFERROR(INDEX(February!$AL:$AL,MATCH($A11,February!$A:$A,0)),0)+IFERROR(INDEX(March!$AO:$AO,MATCH($A11,March!$A:$A,0)),0)+IFERROR(INDEX(April!$AN:$AN,MATCH($A11,April!$A:$A,0)),0)+IFERROR(INDEX(May!$AO:$AO,MATCH($A11,May!$A:$A,0)),0)+IFERROR(INDEX(June!$AN:$AN,MATCH($A11,June!$A:$A,0)),0)+IFERROR(INDEX(July!$AO:$AO,MATCH($A11,July!$A:$A,0)),0)+IFERROR(INDEX(August!$AO:$AO,MATCH($A11,August!$A:$A,0)),0)+IFERROR(INDEX(September!$AN:$AN,MATCH($A11,September!$A:$A,0)),0)+IFERROR(INDEX(October!$AO:$AO,MATCH($A11,October!$A:$A,0)),0)+IFERROR(INDEX(November!$AN:$AN,MATCH($A11,November!$A:$A,0)),0)+IFERROR(INDEX(December!$AO:$AO,MATCH($A11,December!$A:$A,0)),0) -> 12 | X11: =W11/2 -> 6 | Y11: =(IFERROR(INDEX(January!$AL:$AL,MATCH($A11,January!$A:$A,0)),0)+IFERROR(INDEX(February!$AI:$AI,MATCH($A11,February!$A:$A,0)),0)+IFERROR(INDEX(March!$AL:$AL,MATCH($A11,March!$A:$A,0)),0)+IFERROR(INDEX(April!$AK:$AK,MATCH($A11,April!$A:$A,0)),0)+IFERROR(INDEX(May!$AL:$AL,MATCH($A11,May!$A:$A,0)),0)+IFERROR(INDEX(June!$AK:$AK,MATCH($A11,June!$A:$A,0)),0)+IFERROR(INDEX(July!$AL:$AL,MATCH($A11,July!$A:$A,0)),0)+IFERROR(INDEX(August!$AL:$AL,MATCH($A11,August!$A:$A,0)),0)+IFERROR(INDEX(September!$AK:$AK,MATCH($A11,September!$A:$A,0)),0)+IFERROR(INDEX(October!$AL:$AL,MATCH($A11,October!$A:$A,0)),0)+IFERROR(INDEX(November!$AK:$AK,MATCH($A11,November!$A:$A,0)),0)+IFERROR(INDEX(December!$AL:$AL,MATCH($A11,December!$A:$A,0)),0))*0.5 -> 13 | Z11: =IFERROR(INDEX(January!$AK:$AK,MATCH($A11,January!$A:$A,0)),0)+IFERROR(INDEX(February!$AH:$AH,MATCH($A11,February!$A:$A,0)),0)+IFERROR(INDEX(March!$AK:$AK,MATCH($A11,March!$A:$A,0)),0)+IFERROR(INDEX(April!$AJ:$AJ,MATCH($A11,April!$A:$A,0)),0)+IFERROR(INDEX(May!$AK:$AK,MATCH($A11,May!$A:$A,0)),0)+IFERROR(INDEX(June!$AJ:$AJ,MATCH($A11,June!$A:$A,0)),0)+IFERROR(INDEX(July!$AK:$AK,MATCH($A11,July!$A:$A,0)),0)+IFERROR(INDEX(August!$AK:$AK,MATCH($A11,August!$A:$A,0)),0)+IFERROR(INDEX(September!$AJ:$AJ,MATCH($A11,September!$A:$A,0)),0)+IFERROR(INDEX(October!$AK:$AK,MATCH($A11,October!$A:$A,0)),0)+IFERROR(INDEX(November!$AJ:$AJ,MATCH($A11,November!$A:$A,0)),0)+IFERROR(INDEX(December!$AK:$AK,MATCH($A11,December!$A:$A,0)),0) -> 25 | AA11: =Y11+Z11 -> 38 | AB11: 17 | AC11: =AA11+IF(AB11="",0,AB11) -> 55 | AE11: =AC11-IF(AD11="",0,AD11) -> 55
A12: 272 | B12: Nzabamwita.Pascal | C12: ADMN | D12: 21 | E12: 21 | F12: 23 | G12: 15 | H12: 13 | I12: 21 | J12: 21 | K12: 22 | L12: 24 | M12: 24 | N12: 23 | O12: 15 | P12: =IFERROR(INDEX(January!$AI:$AI,MATCH($A12,January!$A:$A,0)),0)+IFERROR(INDEX(February!$AF:$AF,MATCH($A12,February!$A:$A,0)),0)+IFERROR(INDEX(March!$AI:$AI,MATCH($A12,March!$A:$A,0)),0)+IFERROR(INDEX(April!$AH:$AH,MATCH($A12,April!$A:$A,0)),0)+IFERROR(INDEX(May!$AI:$AI,MATCH($A12,May!$A:$A,0)),0)+IFERROR(INDEX(June!$AH:$AH,MATCH($A12,June!$A:$A,0)),0)+IFERROR(INDEX(July!$AI:$AI,MATCH($A12,July!$A:$A,0)),0)+IFERROR(INDEX(August!$AI:$AI,MATCH($A12,August!$A:$A,0)),0)+IFERROR(INDEX(September!$AH:$AH,MATCH($A12,September!$A:$A,0)),0)+IFERROR(INDEX(October!$AI:$AI,MATCH($A12,October!$A:$A,0)),0)+IFERROR(INDEX(November!$AH:$AH,MATCH($A12,November!$A:$A,0)),0)+IFERROR(INDEX(December!$AI:$AI,MATCH($A12,December!$A:$A,0)),0) -> 218 | Q12: =IFERROR(INDEX(January!$AJ:$AJ,MATCH($A12,January!$A:$A,0)),0)+IFERROR(INDEX(February!$AG:$AG,MATCH($A12,February!$A:$A,0)),0)+IFERROR(INDEX(March!$AJ:$AJ,MATCH($A12,March!$A:$A,0)),0)+IFERROR(INDEX(April!$AI:$AI,MATCH($A12,April!$A:$A,0)),0)+IFERROR(INDEX(May!$AJ:$AJ,MATCH($A12,May!$A:$A,0)),0)+IFERROR(INDEX(June!$AI:$AI,MATCH($A12,June!$A:$A,0)),0)+IFERROR(INDEX(July!$AJ:$AJ,MATCH($A12,July!$A:$A,0)),0)+IFERROR(INDEX(August!$AJ:$AJ,MATCH($A12,August!$A:$A,0)),0)+IFERROR(INDEX(September!$AI:$AI,MATCH($A12,September!$A:$A,0)),0)+IFERROR(INDEX(October!$AJ:$AJ,MATCH($A12,October!$A:$A,0)),0)+IFERROR(INDEX(November!$AI:$AI,MATCH($A12,November!$A:$A,0)),0)+IFERROR(INDEX(December!$AJ:$AJ,MATCH($A12,December!$A:$A,0)),0) -> 43 | R12: =IFERROR(INDEX(January!$AK:$AK,MATCH($A12,January!$A:$A,0)),0)+IFERROR(INDEX(February!$AH:$AH,MATCH($A12,February!$A:$A,0)),0)+IFERROR(INDEX(March!$AK:$AK,MATCH($A12,March!$A:$A,0)),0)+IFERROR(INDEX(April!$AJ:$AJ,MATCH($A12,April!$A:$A,0)),0)+IFERROR(INDEX(May!$AK:$AK,MATCH($A12,May!$A:$A,0)),0)+IFERROR(INDEX(June!$AJ:$AJ,MATCH($A12,June!$A:$A,0)),0)+IFERROR(INDEX(July!$AK:$AK,MATCH($A12,July!$A:$A,0)),0)+IFERROR(INDEX(August!$AK:$AK,MATCH($A12,August!$A:$A,0)),0)+IFERROR(INDEX(September!$AJ:$AJ,MATCH($A12,September!$A:$A,0)),0)+IFERROR(INDEX(October!$AK:$AK,MATCH($A12,October!$A:$A,0)),0)+IFERROR(INDEX(November!$AJ:$AJ,MATCH($A12,November!$A:$A,0)),0)+IFERROR(INDEX(December!$AK:$AK,MATCH($A12,December!$A:$A,0)),0) -> 3 | S12: =IF((P12+Q12)=0,"",P12/(P12+Q12)) -> 0.83524904 | U12: =IFERROR(INDEX(January!$AQ:$AQ,MATCH($A12,January!$A:$A,0)),0)+IFERROR(INDEX(February!$AN:$AN,MATCH($A12,February!$A:$A,0)),0)+IFERROR(INDEX(March!$AQ:$AQ,MATCH($A12,March!$A:$A,0)),0)+IFERROR(INDEX(April!$AP:$AP,MATCH($A12,April!$A:$A,0)),0)+IFERROR(INDEX(May!$AQ:$AQ,MATCH($A12,May!$A:$A,0)),0)+IFERROR(INDEX(June!$AP:$AP,MATCH($A12,June!$A:$A,0)),0)+IFERROR(INDEX(July!$AQ:$AQ,MATCH($A12,July!$A:$A,0)),0)+IFERROR(INDEX(August!$AQ:$AQ,MATCH($A12,August!$A:$A,0)),0)+IFERROR(INDEX(September!$AP:$AP,MATCH($A12,September!$A:$A,0)),0)+IFERROR(INDEX(October!$AQ:$AQ,MATCH($A12,October!$A:$A,0)),0)+IFERROR(INDEX(November!$AP:$AP,MATCH($A12,November!$A:$A,0)),0)+IFERROR(INDEX(December!$AQ:$AQ,MATCH($A12,December!$A:$A,0)),0) -> 223 | V12: =IFERROR(INDEX(January!$AJ:$AJ,MATCH($A12,January!$A:$A,0)),0)+IFERROR(INDEX(February!$AG:$AG,MATCH($A12,February!$A:$A,0)),0)+IFERROR(INDEX(March!$AJ:$AJ,MATCH($A12,March!$A:$A,0)),0)+IFERROR(INDEX(April!$AI:$AI,MATCH($A12,April!$A:$A,0)),0)+IFERROR(INDEX(May!$AJ:$AJ,MATCH($A12,May!$A:$A,0)),0)+IFERROR(INDEX(June!$AI:$AI,MATCH($A12,June!$A:$A,0)),0)+IFERROR(INDEX(July!$AJ:$AJ,MATCH($A12,July!$A:$A,0)),0)+IFERROR(INDEX(August!$AJ:$AJ,MATCH($A12,August!$A:$A,0)),0)+IFERROR(INDEX(September!$AI:$AI,MATCH($A12,September!$A:$A,0)),0)+IFERROR(INDEX(October!$AJ:$AJ,MATCH($A12,October!$A:$A,0)),0)+IFERROR(INDEX(November!$AI:$AI,MATCH($A12,November!$A:$A,0)),0)+IFERROR(INDEX(December!$AJ:$AJ,MATCH($A12,December!$A:$A,0)),0) -> 43 | W12: =IFERROR(INDEX(January!$AO:$AO,MATCH($A12,January!$A:$A,0)),0)+IFERROR(INDEX(February!$AL:$AL,MATCH($A12,February!$A:$A,0)),0)+IFERROR(INDEX(March!$AO:$AO,MATCH($A12,March!$A:$A,0)),0)+IFERROR(INDEX(April!$AN:$AN,MATCH($A12,April!$A:$A,0)),0)+IFERROR(INDEX(May!$AO:$AO,MATCH($A12,May!$A:$A,0)),0)+IFERROR(INDEX(June!$AN:$AN,MATCH($A12,June!$A:$A,0)),0)+IFERROR(INDEX(July!$AO:$AO,MATCH($A12,July!$A:$A,0)),0)+IFERROR(INDEX(August!$AO:$AO,MATCH($A12,August!$A:$A,0)),0)+IFERROR(INDEX(September!$AN:$AN,MATCH($A12,September!$A:$A,0)),0)+IFERROR(INDEX(October!$AO:$AO,MATCH($A12,October!$A:$A,0)),0)+IFERROR(INDEX(November!$AN:$AN,MATCH($A12,November!$A:$A,0)),0)+IFERROR(INDEX(December!$AO:$AO,MATCH($A12,December!$A:$A,0)),0) -> 18 | X12: =W12/2 -> 9 | Y12: =(IFERROR(INDEX(January!$AL:$AL,MATCH($A12,January!$A:$A,0)),0)+IFERROR(INDEX(February!$AI:$AI,MATCH($A12,February!$A:$A,0)),0)+IFERROR(INDEX(March!$AL:$AL,MATCH($A12,March!$A:$A,0)),0)+IFERROR(INDEX(April!$AK:$AK,MATCH($A12,April!$A:$A,0)),0)+IFERROR(INDEX(May!$AL:$AL,MATCH($A12,May!$A:$A,0)),0)+IFERROR(INDEX(June!$AK:$AK,MATCH($A12,June!$A:$A,0)),0)+IFERROR(INDEX(July!$AL:$AL,MATCH($A12,July!$A:$A,0)),0)+IFERROR(INDEX(August!$AL:$AL,MATCH($A12,August!$A:$A,0)),0)+IFERROR(INDEX(September!$AK:$AK,MATCH($A12,September!$A:$A,0)),0)+IFERROR(INDEX(October!$AL:$AL,MATCH($A12,October!$A:$A,0)),0)+IFERROR(INDEX(November!$AK:$AK,MATCH($A12,November!$A:$A,0)),0)+IFERROR(INDEX(December!$AL:$AL,MATCH($A12,December!$A:$A,0)),0))*0.5 -> 11 | Z12: =IFERROR(INDEX(January!$AK:$AK,MATCH($A12,January!$A:$A,0)),0)+IFERROR(INDEX(February!$AH:$AH,MATCH($A12,February!$A:$A,0)),0)+IFERROR(INDEX(March!$AK:$AK,MATCH($A12,March!$A:$A,0)),0)+IFERROR(INDEX(April!$AJ:$AJ,MATCH($A12,April!$A:$A,0)),0)+IFERROR(INDEX(May!$AK:$AK,MATCH($A12,May!$A:$A,0)),0)+IFERROR(INDEX(June!$AJ:$AJ,MATCH($A12,June!$A:$A,0)),0)+IFERROR(INDEX(July!$AK:$AK,MATCH($A12,July!$A:$A,0)),0)+IFERROR(INDEX(August!$AK:$AK,MATCH($A12,August!$A:$A,0)),0)+IFERROR(INDEX(September!$AJ:$AJ,MATCH($A12,September!$A:$A,0)),0)+IFERROR(INDEX(October!$AK:$AK,MATCH($A12,October!$A:$A,0)),0)+IFERROR(INDEX(November!$AJ:$AJ,MATCH($A12,November!$A:$A,0)),0)+IFERROR(INDEX(December!$AK:$AK,MATCH($A12,December!$A:$A,0)),0) -> 3 | AA12: =Y12+Z12 -> 14 | AB12: 17 | AC12: =AA12+IF(AB12="",0,AB12) -> 31 | AE12: =AC12-IF(AD12="",0,AD12) -> 31
A13: 276 | B13: Tuyisabe.Jean.Damascene | C13: ADMN | D13: 27 | E13: 21 | F13: 24 | G13: 6 | H13: 9 | I13: 21 | J13: 25 | K13: 19 | L13: 26 | M13: 11 | N13: 9 | O13: 11 | P13: =IFERROR(INDEX(January!$AI:$AI,MATCH($A13,January!$A:$A,0)),0)+IFERROR(INDEX(February!$AF:$AF,MATCH($A13,February!$A:$A,0)),0)+IFERROR(INDEX(March!$AI:$AI,MATCH($A13,March!$A:$A,0)),0)+IFERROR(INDEX(April!$AH:$AH,MATCH($A13,April!$A:$A,0)),0)+IFERROR(INDEX(May!$AI:$AI,MATCH($A13,May!$A:$A,0)),0)+IFERROR(INDEX(June!$AH:$AH,MATCH($A13,June!$A:$A,0)),0)+IFERROR(INDEX(July!$AI:$AI,MATCH($A13,July!$A:$A,0)),0)+IFERROR(INDEX(August!$AI:$AI,MATCH($A13,August!$A:$A,0)),0)+IFERROR(INDEX(September!$AH:$AH,MATCH($A13,September!$A:$A,0)),0)+IFERROR(INDEX(October!$AI:$AI,MATCH($A13,October!$A:$A,0)),0)+IFERROR(INDEX(November!$AH:$AH,MATCH($A13,November!$A:$A,0)),0)+IFERROR(INDEX(December!$AI:$AI,MATCH($A13,December!$A:$A,0)),0) -> 171 | Q13: =IFERROR(INDEX(January!$AJ:$AJ,MATCH($A13,January!$A:$A,0)),0)+IFERROR(INDEX(February!$AG:$AG,MATCH($A13,February!$A:$A,0)),0)+IFERROR(INDEX(March!$AJ:$AJ,MATCH($A13,March!$A:$A,0)),0)+IFERROR(INDEX(April!$AI:$AI,MATCH($A13,April!$A:$A,0)),0)+IFERROR(INDEX(May!$AJ:$AJ,MATCH($A13,May!$A:$A,0)),0)+IFERROR(INDEX(June!$AI:$AI,MATCH($A13,June!$A:$A,0)),0)+IFERROR(INDEX(July!$AJ:$AJ,MATCH($A13,July!$A:$A,0)),0)+IFERROR(INDEX(August!$AJ:$AJ,MATCH($A13,August!$A:$A,0)),0)+IFERROR(INDEX(September!$AI:$AI,MATCH($A13,September!$A:$A,0)),0)+IFERROR(INDEX(October!$AJ:$AJ,MATCH($A13,October!$A:$A,0)),0)+IFERROR(INDEX(November!$AI:$AI,MATCH($A13,November!$A:$A,0)),0)+IFERROR(INDEX(December!$AJ:$AJ,MATCH($A13,December!$A:$A,0)),0) -> 90 | R13: =IFERROR(INDEX(January!$AK:$AK,MATCH($A13,January!$A:$A,0)),0)+IFERROR(INDEX(February!$AH:$AH,MATCH($A13,February!$A:$A,0)),0)+IFERROR(INDEX(March!$AK:$AK,MATCH($A13,March!$A:$A,0)),0)+IFERROR(INDEX(April!$AJ:$AJ,MATCH($A13,April!$A:$A,0)),0)+IFERROR(INDEX(May!$AK:$AK,MATCH($A13,May!$A:$A,0)),0)+IFERROR(INDEX(June!$AJ:$AJ,MATCH($A13,June!$A:$A,0)),0)+IFERROR(INDEX(July!$AK:$AK,MATCH($A13,July!$A:$A,0)),0)+IFERROR(INDEX(August!$AK:$AK,MATCH($A13,August!$A:$A,0)),0)+IFERROR(INDEX(September!$AJ:$AJ,MATCH($A13,September!$A:$A,0)),0)+IFERROR(INDEX(October!$AK:$AK,MATCH($A13,October!$A:$A,0)),0)+IFERROR(INDEX(November!$AJ:$AJ,MATCH($A13,November!$A:$A,0)),0)+IFERROR(INDEX(December!$AK:$AK,MATCH($A13,December!$A:$A,0)),0) -> 19 | S13: =IF((P13+Q13)=0,"",P13/(P13+Q13)) -> 0.65517241 | U13: =IFERROR(INDEX(January!$AQ:$AQ,MATCH($A13,January!$A:$A,0)),0)+IFERROR(INDEX(February!$AN:$AN,MATCH($A13,February!$A:$A,0)),0)+IFERROR(INDEX(March!$AQ:$AQ,MATCH($A13,March!$A:$A,0)),0)+IFERROR(INDEX(April!$AP:$AP,MATCH($A13,April!$A:$A,0)),0)+IFERROR(INDEX(May!$AQ:$AQ,MATCH($A13,May!$A:$A,0)),0)+IFERROR(INDEX(June!$AP:$AP,MATCH($A13,June!$A:$A,0)),0)+IFERROR(INDEX(July!$AQ:$AQ,MATCH($A13,July!$A:$A,0)),0)+IFERROR(INDEX(August!$AQ:$AQ,MATCH($A13,August!$A:$A,0)),0)+IFERROR(INDEX(September!$AP:$AP,MATCH($A13,September!$A:$A,0)),0)+IFERROR(INDEX(October!$AQ:$AQ,MATCH($A13,October!$A:$A,0)),0)+IFERROR(INDEX(November!$AP:$AP,MATCH($A13,November!$A:$A,0)),0)+IFERROR(INDEX(December!$AQ:$AQ,MATCH($A13,December!$A:$A,0)),0) -> 192 | V13: =IFERROR(INDEX(January!$AJ:$AJ,MATCH($A13,January!$A:$A,0)),0)+IFERROR(INDEX(February!$AG:$AG,MATCH($A13,February!$A:$A,0)),0)+IFERROR(INDEX(March!$AJ:$AJ,MATCH($A13,March!$A:$A,0)),0)+IFERROR(INDEX(April!$AI:$AI,MATCH($A13,April!$A:$A,0)),0)+IFERROR(INDEX(May!$AJ:$AJ,MATCH($A13,May!$A:$A,0)),0)+IFERROR(INDEX(June!$AI:$AI,MATCH($A13,June!$A:$A,0)),0)+IFERROR(INDEX(July!$AJ:$AJ,MATCH($A13,July!$A:$A,0)),0)+IFERROR(INDEX(August!$AJ:$AJ,MATCH($A13,August!$A:$A,0)),0)+IFERROR(INDEX(September!$AI:$AI,MATCH($A13,September!$A:$A,0)),0)+IFERROR(INDEX(October!$AJ:$AJ,MATCH($A13,October!$A:$A,0)),0)+IFERROR(INDEX(November!$AI:$AI,MATCH($A13,November!$A:$A,0)),0)+IFERROR(INDEX(December!$AJ:$AJ,MATCH($A13,December!$A:$A,0)),0) -> 90 | W13: =IFERROR(INDEX(January!$AO:$AO,MATCH($A13,January!$A:$A,0)),0)+IFERROR(INDEX(February!$AL:$AL,MATCH($A13,February!$A:$A,0)),0)+IFERROR(INDEX(March!$AO:$AO,MATCH($A13,March!$A:$A,0)),0)+IFERROR(INDEX(April!$AN:$AN,MATCH($A13,April!$A:$A,0)),0)+IFERROR(INDEX(May!$AO:$AO,MATCH($A13,May!$A:$A,0)),0)+IFERROR(INDEX(June!$AN:$AN,MATCH($A13,June!$A:$A,0)),0)+IFERROR(INDEX(July!$AO:$AO,MATCH($A13,July!$A:$A,0)),0)+IFERROR(INDEX(August!$AO:$AO,MATCH($A13,August!$A:$A,0)),0)+IFERROR(INDEX(September!$AN:$AN,MATCH($A13,September!$A:$A,0)),0)+IFERROR(INDEX(October!$AO:$AO,MATCH($A13,October!$A:$A,0)),0)+IFERROR(INDEX(November!$AN:$AN,MATCH($A13,November!$A:$A,0)),0)+IFERROR(INDEX(December!$AO:$AO,MATCH($A13,December!$A:$A,0)),0) -> 15 | X13: =W13/2 -> 7.5 | Y13: =(IFERROR(INDEX(January!$AL:$AL,MATCH($A13,January!$A:$A,0)),0)+IFERROR(INDEX(February!$AI:$AI,MATCH($A13,February!$A:$A,0)),0)+IFERROR(INDEX(March!$AL:$AL,MATCH($A13,March!$A:$A,0)),0)+IFERROR(INDEX(April!$AK:$AK,MATCH($A13,April!$A:$A,0)),0)+IFERROR(INDEX(May!$AL:$AL,MATCH($A13,May!$A:$A,0)),0)+IFERROR(INDEX(June!$AK:$AK,MATCH($A13,June!$A:$A,0)),0)+IFERROR(INDEX(July!$AL:$AL,MATCH($A13,July!$A:$A,0)),0)+IFERROR(INDEX(August!$AL:$AL,MATCH($A13,August!$A:$A,0)),0)+IFERROR(INDEX(September!$AK:$AK,MATCH($A13,September!$A:$A,0)),0)+IFERROR(INDEX(October!$AL:$AL,MATCH($A13,October!$A:$A,0)),0)+IFERROR(INDEX(November!$AK:$AK,MATCH($A13,November!$A:$A,0)),0)+IFERROR(INDEX(December!$AL:$AL,MATCH($A13,December!$A:$A,0)),0))*0.5 -> 9.5 | Z13: =IFERROR(INDEX(January!$AK:$AK,MATCH($A13,January!$A:$A,0)),0)+IFERROR(INDEX(February!$AH:$AH,MATCH($A13,February!$A:$A,0)),0)+IFERROR(INDEX(March!$AK:$AK,MATCH($A13,March!$A:$A,0)),0)+IFERROR(INDEX(April!$AJ:$AJ,MATCH($A13,April!$A:$A,0)),0)+IFERROR(INDEX(May!$AK:$AK,MATCH($A13,May!$A:$A,0)),0)+IFERROR(INDEX(June!$AJ:$AJ,MATCH($A13,June!$A:$A,0)),0)+IFERROR(INDEX(July!$AK:$AK,MATCH($A13,July!$A:$A,0)),0)+IFERROR(INDEX(August!$AK:$AK,MATCH($A13,August!$A:$A,0)),0)+IFERROR(INDEX(September!$AJ:$AJ,MATCH($A13,September!$A:$A,0)),0)+IFERROR(INDEX(October!$AK:$AK,MATCH($A13,October!$A:$A,0)),0)+IFERROR(INDEX(November!$AJ:$AJ,MATCH($A13,November!$A:$A,0)),0)+IFERROR(INDEX(December!$AK:$AK,MATCH($A13,December!$A:$A,0)),0) -> 19 | AA13: =Y13+Z13 -> 28.5 | AB13: 17 | AC13: =AA13+IF(AB13="",0,AB13) -> 45.5 | AE13: =AC13-IF(AD13="",0,AD13) -> 45.5
A14: 277 | B14: Ndandari.Blaise | C14: ADMN | D14: 29 | E14: 26 | F14: 24 | G14: 25 | H14: 25 | I14: 1 | J14: 18 | K14: 25 | L14: 26 | M14: 31 | N14: 24 | O14: 0 | P14: =IFERROR(INDEX(January!$AI:$AI,MATCH($A14,January!$A:$A,0)),0)+IFERROR(INDEX(February!$AF:$AF,MATCH($A14,February!$A:$A,0)),0)+IFERROR(INDEX(March!$AI:$AI,MATCH($A14,March!$A:$A,0)),0)+IFERROR(INDEX(April!$AH:$AH,MATCH($A14,April!$A:$A,0)),0)+IFERROR(INDEX(May!$AI:$AI,MATCH($A14,May!$A:$A,0)),0)+IFERROR(INDEX(June!$AH:$AH,MATCH($A14,June!$A:$A,0)),0)+IFERROR(INDEX(July!$AI:$AI,MATCH($A14,July!$A:$A,0)),0)+IFERROR(INDEX(August!$AI:$AI,MATCH($A14,August!$A:$A,0)),0)+IFERROR(INDEX(September!$AH:$AH,MATCH($A14,September!$A:$A,0)),0)+IFERROR(INDEX(October!$AI:$AI,MATCH($A14,October!$A:$A,0)),0)+IFERROR(INDEX(November!$AH:$AH,MATCH($A14,November!$A:$A,0)),0)+IFERROR(INDEX(December!$AI:$AI,MATCH($A14,December!$A:$A,0)),0) -> 198 | Q14: =IFERROR(INDEX(January!$AJ:$AJ,MATCH($A14,January!$A:$A,0)),0)+IFERROR(INDEX(February!$AG:$AG,MATCH($A14,February!$A:$A,0)),0)+IFERROR(INDEX(March!$AJ:$AJ,MATCH($A14,March!$A:$A,0)),0)+IFERROR(INDEX(April!$AI:$AI,MATCH($A14,April!$A:$A,0)),0)+IFERROR(INDEX(May!$AJ:$AJ,MATCH($A14,May!$A:$A,0)),0)+IFERROR(INDEX(June!$AI:$AI,MATCH($A14,June!$A:$A,0)),0)+IFERROR(INDEX(July!$AJ:$AJ,MATCH($A14,July!$A:$A,0)),0)+IFERROR(INDEX(August!$AJ:$AJ,MATCH($A14,August!$A:$A,0)),0)+IFERROR(INDEX(September!$AI:$AI,MATCH($A14,September!$A:$A,0)),0)+IFERROR(INDEX(October!$AJ:$AJ,MATCH($A14,October!$A:$A,0)),0)+IFERROR(INDEX(November!$AI:$AI,MATCH($A14,November!$A:$A,0)),0)+IFERROR(INDEX(December!$AJ:$AJ,MATCH($A14,December!$A:$A,0)),0) -> 63 | R14: =IFERROR(INDEX(January!$AK:$AK,MATCH($A14,January!$A:$A,0)),0)+IFERROR(INDEX(February!$AH:$AH,MATCH($A14,February!$A:$A,0)),0)+IFERROR(INDEX(March!$AK:$AK,MATCH($A14,March!$A:$A,0)),0)+IFERROR(INDEX(April!$AJ:$AJ,MATCH($A14,April!$A:$A,0)),0)+IFERROR(INDEX(May!$AK:$AK,MATCH($A14,May!$A:$A,0)),0)+IFERROR(INDEX(June!$AJ:$AJ,MATCH($A14,June!$A:$A,0)),0)+IFERROR(INDEX(July!$AK:$AK,MATCH($A14,July!$A:$A,0)),0)+IFERROR(INDEX(August!$AK:$AK,MATCH($A14,August!$A:$A,0)),0)+IFERROR(INDEX(September!$AJ:$AJ,MATCH($A14,September!$A:$A,0)),0)+IFERROR(INDEX(October!$AK:$AK,MATCH($A14,October!$A:$A,0)),0)+IFERROR(INDEX(November!$AJ:$AJ,MATCH($A14,November!$A:$A,0)),0)+IFERROR(INDEX(December!$AK:$AK,MATCH($A14,December!$A:$A,0)),0) -> 28 | S14: =IF((P14+Q14)=0,"",P14/(P14+Q14)) -> 0.75862069 | U14: =IFERROR(INDEX(January!$AQ:$AQ,MATCH($A14,January!$A:$A,0)),0)+IFERROR(INDEX(February!$AN:$AN,MATCH($A14,February!$A:$A,0)),0)+IFERROR(INDEX(March!$AQ:$AQ,MATCH($A14,March!$A:$A,0)),0)+IFERROR(INDEX(April!$AP:$AP,MATCH($A14,April!$A:$A,0)),0)+IFERROR(INDEX(May!$AQ:$AQ,MATCH($A14,May!$A:$A,0)),0)+IFERROR(INDEX(June!$AP:$AP,MATCH($A14,June!$A:$A,0)),0)+IFERROR(INDEX(July!$AQ:$AQ,MATCH($A14,July!$A:$A,0)),0)+IFERROR(INDEX(August!$AQ:$AQ,MATCH($A14,August!$A:$A,0)),0)+IFERROR(INDEX(September!$AP:$AP,MATCH($A14,September!$A:$A,0)),0)+IFERROR(INDEX(October!$AQ:$AQ,MATCH($A14,October!$A:$A,0)),0)+IFERROR(INDEX(November!$AP:$AP,MATCH($A14,November!$A:$A,0)),0)+IFERROR(INDEX(December!$AQ:$AQ,MATCH($A14,December!$A:$A,0)),0) -> 235.5 | V14: =IFERROR(INDEX(January!$AJ:$AJ,MATCH($A14,January!$A:$A,0)),0)+IFERROR(INDEX(February!$AG:$AG,MATCH($A14,February!$A:$A,0)),0)+IFERROR(INDEX(March!$AJ:$AJ,MATCH($A14,March!$A:$A,0)),0)+IFERROR(INDEX(April!$AI:$AI,MATCH($A14,April!$A:$A,0)),0)+IFERROR(INDEX(May!$AJ:$AJ,MATCH($A14,May!$A:$A,0)),0)+IFERROR(INDEX(June!$AI:$AI,MATCH($A14,June!$A:$A,0)),0)+IFERROR(INDEX(July!$AJ:$AJ,MATCH($A14,July!$A:$A,0)),0)+IFERROR(INDEX(August!$AJ:$AJ,MATCH($A14,August!$A:$A,0)),0)+IFERROR(INDEX(September!$AI:$AI,MATCH($A14,September!$A:$A,0)),0)+IFERROR(INDEX(October!$AJ:$AJ,MATCH($A14,October!$A:$A,0)),0)+IFERROR(INDEX(November!$AI:$AI,MATCH($A14,November!$A:$A,0)),0)+IFERROR(INDEX(December!$AJ:$AJ,MATCH($A14,December!$A:$A,0)),0) -> 63 | W14: =IFERROR(INDEX(January!$AO:$AO,MATCH($A14,January!$A:$A,0)),0)+IFERROR(INDEX(February!$AL:$AL,MATCH($A14,February!$A:$A,0)),0)+IFERROR(INDEX(March!$AO:$AO,MATCH($A14,March!$A:$A,0)),0)+IFERROR(INDEX(April!$AN:$AN,MATCH($A14,April!$A:$A,0)),0)+IFERROR(INDEX(May!$AO:$AO,MATCH($A14,May!$A:$A,0)),0)+IFERROR(INDEX(June!$AN:$AN,MATCH($A14,June!$A:$A,0)),0)+IFERROR(INDEX(July!$AO:$AO,MATCH($A14,July!$A:$A,0)),0)+IFERROR(INDEX(August!$AO:$AO,MATCH($A14,August!$A:$A,0)),0)+IFERROR(INDEX(September!$AN:$AN,MATCH($A14,September!$A:$A,0)),0)+IFERROR(INDEX(October!$AO:$AO,MATCH($A14,October!$A:$A,0)),0)+IFERROR(INDEX(November!$AN:$AN,MATCH($A14,November!$A:$A,0)),0)+IFERROR(INDEX(December!$AO:$AO,MATCH($A14,December!$A:$A,0)),0) -> 9 | X14: =W14/2 -> 4.5 | Y14: =(IFERROR(INDEX(January!$AL:$AL,MATCH($A14,January!$A:$A,0)),0)+IFERROR(INDEX(February!$AI:$AI,MATCH($A14,February!$A:$A,0)),0)+IFERROR(INDEX(March!$AL:$AL,MATCH($A14,March!$A:$A,0)),0)+IFERROR(INDEX(April!$AK:$AK,MATCH($A14,April!$A:$A,0)),0)+IFERROR(INDEX(May!$AL:$AL,MATCH($A14,May!$A:$A,0)),0)+IFERROR(INDEX(June!$AK:$AK,MATCH($A14,June!$A:$A,0)),0)+IFERROR(INDEX(July!$AL:$AL,MATCH($A14,July!$A:$A,0)),0)+IFERROR(INDEX(August!$AL:$AL,MATCH($A14,August!$A:$A,0)),0)+IFERROR(INDEX(September!$AK:$AK,MATCH($A14,September!$A:$A,0)),0)+IFERROR(INDEX(October!$AL:$AL,MATCH($A14,October!$A:$A,0)),0)+IFERROR(INDEX(November!$AK:$AK,MATCH($A14,November!$A:$A,0)),0)+IFERROR(INDEX(December!$AL:$AL,MATCH($A14,December!$A:$A,0)),0))*0.5 -> 14 | Z14: =IFERROR(INDEX(January!$AK:$AK,MATCH($A14,January!$A:$A,0)),0)+IFERROR(INDEX(February!$AH:$AH,MATCH($A14,February!$A:$A,0)),0)+IFERROR(INDEX(March!$AK:$AK,MATCH($A14,March!$A:$A,0)),0)+IFERROR(INDEX(April!$AJ:$AJ,MATCH($A14,April!$A:$A,0)),0)+IFERROR(INDEX(May!$AK:$AK,MATCH($A14,May!$A:$A,0)),0)+IFERROR(INDEX(June!$AJ:$AJ,MATCH($A14,June!$A:$A,0)),0)+IFERROR(INDEX(July!$AK:$AK,MATCH($A14,July!$A:$A,0)),0)+IFERROR(INDEX(August!$AK:$AK,MATCH($A14,August!$A:$A,0)),0)+IFERROR(INDEX(September!$AJ:$AJ,MATCH($A14,September!$A:$A,0)),0)+IFERROR(INDEX(October!$AK:$AK,MATCH($A14,October!$A:$A,0)),0)+IFERROR(INDEX(November!$AJ:$AJ,MATCH($A14,November!$A:$A,0)),0)+IFERROR(INDEX(December!$AK:$AK,MATCH($A14,December!$A:$A,0)),0) -> 28 | AA14: =Y14+Z14 -> 42 | AB14: 17 | AC14: =AA14+IF(AB14="",0,AB14) -> 59 | AE14: =AC14-IF(AD14="",0,AD14) -> 59
A15: 278 | B15: Ndayizeye.Pascal | C15: ADMN | D15: 19 | E15: 23 | F15: 27 | G15: 4 | H15: 25 | I15: 24 | J15: 11 | K15: 0 | L15: 28 | M15: 3 | N15: 21 | O15: 23 | P15: =IFERROR(INDEX(January!$AI:$AI,MATCH($A15,January!$A:$A,0)),0)+IFERROR(INDEX(February!$AF:$AF,MATCH($A15,February!$A:$A,0)),0)+IFERROR(INDEX(March!$AI:$AI,MATCH($A15,March!$A:$A,0)),0)+IFERROR(INDEX(April!$AH:$AH,MATCH($A15,April!$A:$A,0)),0)+IFERROR(INDEX(May!$AI:$AI,MATCH($A15,May!$A:$A,0)),0)+IFERROR(INDEX(June!$AH:$AH,MATCH($A15,June!$A:$A,0)),0)+IFERROR(INDEX(July!$AI:$AI,MATCH($A15,July!$A:$A,0)),0)+IFERROR(INDEX(August!$AI:$AI,MATCH($A15,August!$A:$A,0)),0)+IFERROR(INDEX(September!$AH:$AH,MATCH($A15,September!$A:$A,0)),0)+IFERROR(INDEX(October!$AI:$AI,MATCH($A15,October!$A:$A,0)),0)+IFERROR(INDEX(November!$AH:$AH,MATCH($A15,November!$A:$A,0)),0)+IFERROR(INDEX(December!$AI:$AI,MATCH($A15,December!$A:$A,0)),0) -> 166 | Q15: =IFERROR(INDEX(January!$AJ:$AJ,MATCH($A15,January!$A:$A,0)),0)+IFERROR(INDEX(February!$AG:$AG,MATCH($A15,February!$A:$A,0)),0)+IFERROR(INDEX(March!$AJ:$AJ,MATCH($A15,March!$A:$A,0)),0)+IFERROR(INDEX(April!$AI:$AI,MATCH($A15,April!$A:$A,0)),0)+IFERROR(INDEX(May!$AJ:$AJ,MATCH($A15,May!$A:$A,0)),0)+IFERROR(INDEX(June!$AI:$AI,MATCH($A15,June!$A:$A,0)),0)+IFERROR(INDEX(July!$AJ:$AJ,MATCH($A15,July!$A:$A,0)),0)+IFERROR(INDEX(August!$AJ:$AJ,MATCH($A15,August!$A:$A,0)),0)+IFERROR(INDEX(September!$AI:$AI,MATCH($A15,September!$A:$A,0)),0)+IFERROR(INDEX(October!$AJ:$AJ,MATCH($A15,October!$A:$A,0)),0)+IFERROR(INDEX(November!$AI:$AI,MATCH($A15,November!$A:$A,0)),0)+IFERROR(INDEX(December!$AJ:$AJ,MATCH($A15,December!$A:$A,0)),0) -> 95 | R15: =IFERROR(INDEX(January!$AK:$AK,MATCH($A15,January!$A:$A,0)),0)+IFERROR(INDEX(February!$AH:$AH,MATCH($A15,February!$A:$A,0)),0)+IFERROR(INDEX(March!$AK:$AK,MATCH($A15,March!$A:$A,0)),0)+IFERROR(INDEX(April!$AJ:$AJ,MATCH($A15,April!$A:$A,0)),0)+IFERROR(INDEX(May!$AK:$AK,MATCH($A15,May!$A:$A,0)),0)+IFERROR(INDEX(June!$AJ:$AJ,MATCH($A15,June!$A:$A,0)),0)+IFERROR(INDEX(July!$AK:$AK,MATCH($A15,July!$A:$A,0)),0)+IFERROR(INDEX(August!$AK:$AK,MATCH($A15,August!$A:$A,0)),0)+IFERROR(INDEX(September!$AJ:$AJ,MATCH($A15,September!$A:$A,0)),0)+IFERROR(INDEX(October!$AK:$AK,MATCH($A15,October!$A:$A,0)),0)+IFERROR(INDEX(November!$AJ:$AJ,MATCH($A15,November!$A:$A,0)),0)+IFERROR(INDEX(December!$AK:$AK,MATCH($A15,December!$A:$A,0)),0) -> 21 | S15: =IF((P15+Q15)=0,"",P15/(P15+Q15)) -> 0.63601533 | U15: =IFERROR(INDEX(January!$AQ:$AQ,MATCH($A15,January!$A:$A,0)),0)+IFERROR(INDEX(February!$AN:$AN,MATCH($A15,February!$A:$A,0)),0)+IFERROR(INDEX(March!$AQ:$AQ,MATCH($A15,March!$A:$A,0)),0)+IFERROR(INDEX(April!$AP:$AP,MATCH($A15,April!$A:$A,0)),0)+IFERROR(INDEX(May!$AQ:$AQ,MATCH($A15,May!$A:$A,0)),0)+IFERROR(INDEX(June!$AP:$AP,MATCH($A15,June!$A:$A,0)),0)+IFERROR(INDEX(July!$AQ:$AQ,MATCH($A15,July!$A:$A,0)),0)+IFERROR(INDEX(August!$AQ:$AQ,MATCH($A15,August!$A:$A,0)),0)+IFERROR(INDEX(September!$AP:$AP,MATCH($A15,September!$A:$A,0)),0)+IFERROR(INDEX(October!$AQ:$AQ,MATCH($A15,October!$A:$A,0)),0)+IFERROR(INDEX(November!$AP:$AP,MATCH($A15,November!$A:$A,0)),0)+IFERROR(INDEX(December!$AQ:$AQ,MATCH($A15,December!$A:$A,0)),0) -> 192.5 | V15: =IFERROR(INDEX(January!$AJ:$AJ,MATCH($A15,January!$A:$A,0)),0)+IFERROR(INDEX(February!$AG:$AG,MATCH($A15,February!$A:$A,0)),0)+IFERROR(INDEX(March!$AJ:$AJ,MATCH($A15,March!$A:$A,0)),0)+IFERROR(INDEX(April!$AI:$AI,MATCH($A15,April!$A:$A,0)),0)+IFERROR(INDEX(May!$AJ:$AJ,MATCH($A15,May!$A:$A,0)),0)+IFERROR(INDEX(June!$AI:$AI,MATCH($A15,June!$A:$A,0)),0)+IFERROR(INDEX(July!$AJ:$AJ,MATCH($A15,July!$A:$A,0)),0)+IFERROR(INDEX(August!$AJ:$AJ,MATCH($A15,August!$A:$A,0)),0)+IFERROR(INDEX(September!$AI:$AI,MATCH($A15,September!$A:$A,0)),0)+IFERROR(INDEX(October!$AJ:$AJ,MATCH($A15,October!$A:$A,0)),0)+IFERROR(INDEX(November!$AI:$AI,MATCH($A15,November!$A:$A,0)),0)+IFERROR(INDEX(December!$AJ:$AJ,MATCH($A15,December!$A:$A,0)),0) -> 95 | W15: =IFERROR(INDEX(January!$AO:$AO,MATCH($A15,January!$A:$A,0)),0)+IFERROR(INDEX(February!$AL:$AL,MATCH($A15,February!$A:$A,0)),0)+IFERROR(INDEX(March!$AO:$AO,MATCH($A15,March!$A:$A,0)),0)+IFERROR(INDEX(April!$AN:$AN,MATCH($A15,April!$A:$A,0)),0)+IFERROR(INDEX(May!$AO:$AO,MATCH($A15,May!$A:$A,0)),0)+IFERROR(INDEX(June!$AN:$AN,MATCH($A15,June!$A:$A,0)),0)+IFERROR(INDEX(July!$AO:$AO,MATCH($A15,July!$A:$A,0)),0)+IFERROR(INDEX(August!$AO:$AO,MATCH($A15,August!$A:$A,0)),0)+IFERROR(INDEX(September!$AN:$AN,MATCH($A15,September!$A:$A,0)),0)+IFERROR(INDEX(October!$AO:$AO,MATCH($A15,October!$A:$A,0)),0)+IFERROR(INDEX(November!$AN:$AN,MATCH($A15,November!$A:$A,0)),0)+IFERROR(INDEX(December!$AO:$AO,MATCH($A15,December!$A:$A,0)),0) -> 10 | X15: =W15/2 -> 5 | Y15: =(IFERROR(INDEX(January!$AL:$AL,MATCH($A15,January!$A:$A,0)),0)+IFERROR(INDEX(February!$AI:$AI,MATCH($A15,February!$A:$A,0)),0)+IFERROR(INDEX(March!$AL:$AL,MATCH($A15,March!$A:$A,0)),0)+IFERROR(INDEX(April!$AK:$AK,MATCH($A15,April!$A:$A,0)),0)+IFERROR(INDEX(May!$AL:$AL,MATCH($A15,May!$A:$A,0)),0)+IFERROR(INDEX(June!$AK:$AK,MATCH($A15,June!$A:$A,0)),0)+IFERROR(INDEX(July!$AL:$AL,MATCH($A15,July!$A:$A,0)),0)+IFERROR(INDEX(August!$AL:$AL,MATCH($A15,August!$A:$A,0)),0)+IFERROR(INDEX(September!$AK:$AK,MATCH($A15,September!$A:$A,0)),0)+IFERROR(INDEX(October!$AL:$AL,MATCH($A15,October!$A:$A,0)),0)+IFERROR(INDEX(November!$AK:$AK,MATCH($A15,November!$A:$A,0)),0)+IFERROR(INDEX(December!$AL:$AL,MATCH($A15,December!$A:$A,0)),0))*0.5 -> 10.5 | Z15: =IFERROR(INDEX(January!$AK:$AK,MATCH($A15,January!$A:$A,0)),0)+IFERROR(INDEX(February!$AH:$AH,MATCH($A15,February!$A:$A,0)),0)+IFERROR(INDEX(March!$AK:$AK,MATCH($A15,March!$A:$A,0)),0)+IFERROR(INDEX(April!$AJ:$AJ,MATCH($A15,April!$A:$A,0)),0)+IFERROR(INDEX(May!$AK:$AK,MATCH($A15,May!$A:$A,0)),0)+IFERROR(INDEX(June!$AJ:$AJ,MATCH($A15,June!$A:$A,0)),0)+IFERROR(INDEX(July!$AK:$AK,MATCH($A15,July!$A:$A,0)),0)+IFERROR(INDEX(August!$AK:$AK,MATCH($A15,August!$A:$A,0)),0)+IFERROR(INDEX(September!$AJ:$AJ,MATCH($A15,September!$A:$A,0)),0)+IFERROR(INDEX(October!$AK:$AK,MATCH($A15,October!$A:$A,0)),0)+IFERROR(INDEX(November!$AJ:$AJ,MATCH($A15,November!$A:$A,0)),0)+IFERROR(INDEX(December!$AK:$AK,MATCH($A15,December!$A:$A,0)),0) -> 21 | AA15: =Y15+Z15 -> 31.5 | AB15: 17 | AC15: =AA15+IF(AB15="",0,AB15) -> 48.5 | AE15: =AC15-IF(AD15="",0,AD15) -> 48.5
